Workbook

Sheet Portada
E3: RUBRICAS
E5: RETO 1
E7: Fechas | F7: XX/XX/2026
F8: XX/XX/2026 | J8: GRUPO
E10: 2 DAW | J10: ALUMNOS
E11: 26/27 | J11: 1 | K11: Name
J12: 2 | K12: Name
J13: 3 | K13: -
J14: 4 | K14: -

Sheet DIW
B3: FASE 1
C4: 0 | D4: 0.33 | E4: 0.66 | F4: 1 | G4: PESO | H4: CORRECCIÓN | I4: NOTA
B5: DISEÑO Y PLANIFICACIÓN | H5: [0, 1, 2, 3]
B6: Descripción de la idea | C6: No explica o explica muy mal la idea que tiene del proyecto. | D6: Explica aunque con poco detalle y/o lo explicado no se ajusta a lo que se pide. | E6: Explica con bastante detalle y lo explicado se ajusta a lo que se pide. | F6: Explica con total detalle y además se ajusta a lo que se pedía. | G6: 1 | I6: =IFERROR(_xlfn.SWITCH($H6, 0, $C$4, 1, $D$4, 2, $E$4, 3, $F$4, "Error") * $G6, "Error") -> 0
B7: Cantidad wireframes | C7: Aporta menos de 4 wireframes. | D7: Aporta entre 4 y 5 wireframes | E7: Aporta entre 6 y 7 wireframes | F7: Aporta 8 o más wireframes. | G7: 0.5 | I7: =IFERROR(_xlfn.SWITCH($H7, 0, $C$4, 1, $D$4, 2, $E$4, 3, $F$4, "Error") * $G7, "Error") -> 0
B8: Calidad de wireframes | C8: Los wireframes no muestran todos los elementos que necesita la página, no muestra nada de homogeneidad y no reflejan una correcta gestión de espacios vacíos. | D8: Los wireframes muestran todos los elementos que necesita la página pero no muestra nada de homogeneidad o no reflejan una correcta gestión de espacios vacíos. | E8: Los wireframes no muestran todos los elementos que necesita la página o no muestra nada de homogeneidad o no reflejan una correcta gestión de espacios vacíos. Una de los aspectos mal pero los otros dos bien. | F8: Los wireframes muestran todos los elementos que necesita la página, se respeta una homogeneidad y reflejan una correcta gestión de espacios vacíos. | G8: 0.5 | I8: =IFERROR(_xlfn.SWITCH($H8, 0, $C$4, 1, $D$4, 2, $E$4, 3, $F$4, "Error") * $G8, "Error") -> 0
B9: Fecha límite de entrega el jueves XX/XX/XXXX a las XX:XX mediante el Classroom | G9: =SUM(G5:G8) -> 2 | I9: =SUM(I5:I8) -> 0
B13: FASE 2
C14: 0 | D14: 0.33 | E14: 0.66 | F14: 1 | G14: PESO | H14: CORRECCIÓN | I14: NOTA
B15: DESARROLLO Y DEPURACIÓN | H15: [0, 1, 2, 3]
B16: Homogeneidad y equilibrio | C16: El sitio web no muestra una homogeneidad entres sus páginas ni un equilibrio entre sus elementos. | D16: Muestra poca homogeneidad y equilibrio. | E16: Muestra bastante homogeneidad y equilibrio. | F16: El sitio web muestra una homogeneidad entres sus páginas y un equilibrio entre sus elementos. | G16: 0.75 | I16: =IFERROR(_xlfn.SWITCH($H16, 0, $C$4, 1, $D$4, 2, $E$4, 3, $F$4, "Error") * $G16, "Error") -> 0
B17: Color | C17: No se usa una combinación de colores adecuada. | D17: La combinación de colores es muy mejorable. | E17: La combinación de colores es bastante buena. | F17: La combinación de colores es excelente. | G17: 0.5 | I17: =IFERROR(_xlfn.SWITCH($H17, 0, $C$4, 1, $D$4, 2, $E$4, 3, $F$4, "Error") * $G17, "Error") -> 0
B18: Tipografía | C18: No se utilizan unas tipografías adecuadas, no existe armonía entre ellas y además no se juega con tamaños y grosores. | D18: Se utilizan unas tipografías legibles, pero no existe armonía entre ellas y además no se juega con tamaños y grosores. | E18: Se utilizan unas tipografías legibles, pero no existe armonía entre ellas o no se juega con tamaños y grosores. | F18: Se utilizan unas tipografías legibles, existe armonía entre ellas y además se juega con tamaños y grosores. | G18: 0.25 | I18: =IFERROR(_xlfn.SWITCH($H18, 0, $C$4, 1, $D$4, 2, $E$4, 3, $F$4, "Error") * $G18, "Error") -> 0
B19: Iconografía | C19: No se usa. | D19: Se usa pero muy poco o se abusa de ella y no es del todo comprensible. | E19: Se usa pero muy poco o se abusa de ella o no es del todo comprensible. | F19: Se usa en su justa medida y además es muy intuitiva y comprensible. | G19: 0.5 | I19: =IFERROR(_xlfn.SWITCH($H19, 0, $C$4, 1, $D$4, 2, $E$4, 3, $F$4, "Error") * $G19, "Error") -> 0
B20: Cabecera | C20: No se usa. | F20: Se usa. | G20: 0.25 | I20: =IFERROR(_xlfn.SWITCH($H20, 0, $C$4, 1, $D$4, 2, $E$4, 3, $F$4, "Error") * $G20, "Error") -> 0
B21: Sistema de navegación | C21: No es adecuado o es inexistente. | D21: No es del todo adecuado, siendo poco intuitivo o presentando fallos. | E21: Presenta algún fallo pero es intuitivo. | F21: No presenta ningún fallo y es muy intuitivo. | G21: 0.5 | I21: =IFERROR(_xlfn.SWITCH($H21, 0, $C$4, 1, $D$4, 2, $E$4, 3, $F$4, "Error") * $G21, "Error") -> 0
B22: Pié de página | C22: No se usa. | F22: Se usa. | G22: 0.25 | I22: =IFERROR(_xlfn.SWITCH($H22, 0, $C$4, 1, $D$4, 2, $E$4, 3, $F$4, "Error") * $G22, "Error") -> 0
B23: Estilos | C23: No se aplica lo aprendido en esta evaluación respecto a las hojas de estilos. | D23: Se aplica algo de lo aprendido respecto a hojas de estilos pero no presenta un estilo atractivo y funcional. | E23: Se aplica bastante de lo aprendido, el sitio web es bastante atractivo y funcional, pero presenta algún error o no se aplica todo de la manera adecuada. | F23: Se aplica mucho de lo aprendido, el sitio web es muy atractivo y funcional. Además todo lo aplicado se aplica de la manera adecuada y sin errores. | G23: 3 | I23: =IFERROR(_xlfn.SWITCH($H23, 0, $C$4, 1, $D$4, 2, $E$4, 3, $F$4, "Error") * $G23, "Error") -> 0
B24: Responsive / adaptative | C24: No existe un diseño responsive o adaptativo | D24: Existe un diseño responsivo o adaptativo pero no es correcto ya que presenta muchos errores y su diseño no es el correcto. | E24: Existe un diseño responsivo o adaptativo pero no es del todo correcto ya que presenta unos pocos errores y su diseño no es del todo correcto. | F24: Existe un diseño responsivo o adaptativo que no presenta errores y su diseño es excelente. | G24: 1.5 | I24: =IFERROR(_xlfn.SWITCH($H24, 0, $C$4, 1, $D$4, 2, $E$4, 3, $F$4, "Error") * $G24, "Error") -> 0
B25: Indentación y limpieza del código | C25: El código no está indentado, está desordenado y no está limpio. | F25: El código está indentado, está ordenado y está limpio y con comentarios que aportan información sobre el código. | G25: 0.5 | I25: =IFERROR(_xlfn.SWITCH($H25, 0, $C$4, 1, $D$4, 2, $E$4, 3, $F$4, "Error") * $G25, "Error") -> 0
B26: Fecha límite de entrega el miércoles XX/XX/XXXX a las XX:XX mediante GitHub | G26: =SUM(G15:G25) -> 8 | I26: =SUM(I15:I25) -> 0
B30: FASE 4
C31: 0 | D31: 0.33 | E31: 0.66 | F31: 1 | G31: PESO | H31: CORRECCIÓN
B32: DEFENSA | G32: % sobre el total de la fase 2 | H32: [0, 1, 2, 3]
B33: Análisis de código y respuesta de cuestiones sobre el mismo | C33: No conoce el código, no sabe responder a ninguna de las cuestiones que se le plantean sobre éste y no conoce el funcionamiento de parte inportante de su proyecto. | D33: Conoce el código en su gran mayoría pero no sabe responder a bastantes cuestiones sobre el mismo ni sabe justificar su uso o funcionamiento. | E33: Conoce el código en su totalidad pero no sabe responder a algunas de las cuestiones sobre éste ni justificar su uso. | F33: Conoce el código en su totalidad y además sabe responder perfectamente todas las cuestiones y justifica por qué lo usó en cada caso.
B34: Durante las tres últimas horas del jueves XX/XX/XXXX
B35: Evaluación individual

Sheet DWEC
B3: FASE 2
C4: 0 | D4: 0.33 | E4: 0.66 | F4: 1 | G4: PESO | H4: CORRECCIÓN | I4: NOTA
B5: DESARROLLO Y DEPURACIÓN | H5: [0, 1, 2, 3]
B6: Variables
B7: Definición de variables | C7: La mayoría de las variables no tienen un nombre descriptivo, no se respetan las reglas nominales o no están definidas del tipo adecuado (const, let, var) o en el ámbito correcto (local, global). | D7: Tres o más variables no tienen un nombre descriptivo, no se respetan las reglas nominales o no están definidas del tipo adecuado (const, let, var) o en el ámbito correcto (local, global). | E7: Una o dos variables no tienen un nombre descriptivo, no se respetan las reglas nominales o no están definidas del tipo adecuado (const, let, var) o en el ámbito correcto (local, global). | F7: Todas las variables tienen un nombre descriptivo, se respetan las reglas nominales y están definidas del tipo adecuado (const, let, var) y en el ámbito correcto (local, global). | G7: 0.75 | I7: =IFERROR(_xlfn.SWITCH($H7, 0, $C$4, 1, $D$4, 2, $E$4, 3, $F$4, "Error") * $G7, "Error") -> 0
B8: Estr. condicionales y repetitivas
B9: if / if...else / if... else if | C9: No se usa. | F9: Se usa. | G9: 0.1 | I9: =IFERROR(_xlfn.SWITCH($H9, 0, $C$4, 1, $D$4, 2, $E$4, 3, $F$4, "Error") * $G9, "Error") -> 0
B10: switch () {case... | C10: No se usa. | F10: Se usa. | G10: 0.1 | I10: =IFERROR(_xlfn.SWITCH($H10, 0, $C$4, 1, $D$4, 2, $E$4, 3, $F$4, "Error") * $G10, "Error") -> 0
B11: for | C11: No se usa. | F11: Se usa. | G11: 0.1 | I11: =IFERROR(_xlfn.SWITCH($H11, 0, $C$4, 1, $D$4, 2, $E$4, 3, $F$4, "Error") * $G11, "Error") -> 0
B12: while / do...while | C12: No se usa. | F12: Se usa. | G12: 0.1 | I12: =IFERROR(_xlfn.SWITCH($H12, 0, $C$4, 1, $D$4, 2, $E$4, 3, $F$4, "Error") * $G12, "Error") -> 0
B13: forEach | C13: No se usa. | F13: Se usa. | G13: 0.1 | I13: =IFERROR(_xlfn.SWITCH($H13, 0, $C$4, 1, $D$4, 2, $E$4, 3, $F$4, "Error") * $G13, "Error") -> 0
B14: Funciones
B15: Número funciones | C15: Se usan 1 o menos. | D15: Se usan 2 o 3. | E15: Se usan 4 o 5. | F15: Se usan más de 5. | G15: 0.5 | I15: =IFERROR(_xlfn.SWITCH($H15, 0, $C$4, 1, $D$4, 2, $E$4, 3, $F$4, "Error") * $G15, "Error") -> 0
B16: Definición de funciones | C16: La mayoría de las funciones no tienen un nombre descriptivo ni respetan las reglas nominales. | D16: Dos o más funciones no tienen un nombre descriptivo ni respetan las reglas nominales. | E16: Una sola función no tiene un nombre descriptivo ni respeta las reglas nominales. | F16: Todas las funciones tienen un nombre descriptivo y respetan las reglas nominales. | G16: 0.25 | I16: =IFERROR(_xlfn.SWITCH($H16, 0, $C$4, 1, $D$4, 2, $E$4, 3, $F$4, "Error") * $G16, "Error") -> 0
B17: Errores en funciones | C17: No presenta errores | D17: Presenta un error | E17: Presenta dos errores | F17: Presenta tres o más errores | G17: -0.5 | I17: =IFERROR(_xlfn.SWITCH($H17, 0, $C$4, 1, $D$4, 2, $E$4, 3, $F$4, "Error") * $G17, "Error") -> 0
B18: Objetos predefinidos
B19: Date / Math / Number / String / Window | C19: No utiliza objetos predefinidos ni sus propiedades y métodos | D19: Utiliza objetos predefinidos y sus propiedades y métodos una vez sin errores o de dos tipos pero comete errores al hacerlo. | E19: Utiliza objetos predefinidos y sus propiedades y métodos en dos ocasiones (tipos distintos) sin errores o al menos de tres tipos pero comete errores al hacerlo. | F19: Utiliza objetos predefinidos y sus propiedades y métodos al menos de tres tipos sin errores. | G19: 0.5 | I19: =IFERROR(_xlfn.SWITCH($H19, 0, $C$4, 1, $D$4, 2, $E$4, 3, $F$4, "Error") * $G19, "Error") -> 0
B20: Arrays
B21: Uso de array | C21: No usa arrays | D21: Usa con sentido una sola vez arrays | E21: Usa con sentido dos veces arrays | F21: Usa con sentido más de dos veces arrays | G21: 0.5 | I21: =IFERROR(_xlfn.SWITCH($H21, 0, $C$4, 1, $D$4, 2, $E$4, 3, $F$4, "Error") * $G21, "Error") -> 0
B22: Propiedades y métodos | C22: No usa propiedades ni métodos | D22: Utiliza un solo método o propiedad distinta | E22: Usa dos métodos o propiedades distintas | F22: Usa tres o más métodos o propiedades distintas | G22: 0.5 | I22: =IFERROR(_xlfn.SWITCH($H22, 0, $C$4, 1, $D$4, 2, $E$4, 3, $F$4, "Error") * $G22, "Error") -> 0
B23: Errores en arrays | C23: No presenta errores | D23: Presenta un error | E23: Presenta dos errores | F23: Presenta tres o más errores | G23: -0.66 | I23: =IFERROR(_xlfn.SWITCH($H23, 0, $C$4, 1, $D$4, 2, $E$4, 3, $F$4, "Error") * $G23, "Error") -> 0
B24: Objetos
B25: Propiedades de objeto | C25: No se definen y usan | D25: Se define y se usa una | E25: Se definen y se usan dos | F25: Se definen y se usan tres o más. | G25: 0.25 | I25: =IFERROR(_xlfn.SWITCH($H25, 0, $C$4, 1, $D$4, 2, $E$4, 3, $F$4, "Error") * $G25, "Error") -> 0
B26: Métodos de objeto | C26: No se definen y usan | D26: Se define y se usa una | E26: Se definen y se usan dos | F26: Se definen y se usan tres o más. | G26: 0.5 | I26: =IFERROR(_xlfn.SWITCH($H26, 0, $C$4, 1, $D$4, 2, $E$4, 3, $F$4, "Error") * $G26, "Error") -> 0
B27: Errores en objetos | C27: No presenta errores | D27: Presenta un error | E27: Presenta dos errores | F27: Presenta tres o más errores | G27: -0.5 | I27: =IFERROR(_xlfn.SWITCH($H27, 0, $C$4, 1, $D$4, 2, $E$4, 3, $F$4, "Error") * $G27, "Error") -> 0
B28: Eventos
B29: Gestión de eventos | C29: No se usan eventos | D29: Se captura un evento | E29: Se capturan dos eventos | F29: Se capturan tres o más eventos | G29: 1 | I29: =IFERROR(_xlfn.SWITCH($H29, 0, $C$4, 1, $D$4, 2, $E$4, 3, $F$4, "Error") * $G29, "Error") -> 0
B30: Errores eventos | C30: No presenta errores | D30: Presenta un error | E30: Presenta dos errores | F30: Presenta tres o más errores | G30: -0.66 | I30: =IFERROR(_xlfn.SWITCH($H30, 0, $C$4, 1, $D$4, 2, $E$4, 3, $F$4, "Error") * $G30, "Error") -> 0
B31: Formulario
B32: Uso formularios | C32: No se usan formularios | F32: Se usan formularios | G32: 0.5 | I32: =IFERROR(_xlfn.SWITCH($H32, 0, $C$4, 1, $D$4, 2, $E$4, 3, $F$4, "Error") * $G32, "Error") -> 0
B33: Errores formularios | C33: No presenta errores | D33: Presenta un error | E33: Presenta dos errores | F33: Presenta tres o más errores | G33: -0.33 | I33: =IFERROR(_xlfn.SWITCH($H33, 0, $C$4, 1, $D$4, 2, $E$4, 3, $F$4, "Error") * $G33, "Error") -> 0
B34: Web Storage
B35: Uso sessionStorage | C35: No utiliza o utiliza sin sentido | F35: Utiliza con sentido | G35: 0.25 | I35: =IFERROR(_xlfn.SWITCH($H35, 0, $C$4, 1, $D$4, 2, $E$4, 3, $F$4, "Error") * $G35, "Error") -> 0
B36: Errores sessionStorage | C36: No presenta errores | D36: Presenta un error | E36: Presenta dos errores | F36: Presenta tres o más errores | G36: -0.166 | I36: =IFERROR(_xlfn.SWITCH($H36, 0, $C$4, 1, $D$4, 2, $E$4, 3, $F$4, "Error") * $G36, "Error") -> 0
B37: Uso localStorage | C37: No utiliza o utiliza sin sentido | F37: Utiliza con sentido | G37: 0.5 | I37: =IFERROR(_xlfn.SWITCH($H37, 0, $C$4, 1, $D$4, 2, $E$4, 3, $F$4, "Error") * $G37, "Error") -> 0
B38: Errores localStorage | C38: No presenta errores | D38: Presenta un error | E38: Presenta dos errores | F38: Presenta tres o más errores | G38: -0.33 | I38: =IFERROR(_xlfn.SWITCH($H38, 0, $C$4, 1, $D$4, 2, $E$4, 3, $F$4, "Error") * $G38, "Error") -> 0
B39: DOM
B40: Modificación DOM | C40: No utiliza o utiliza sin sentido | F40: Utiliza con sentido | G40: 0.25 | I40: =IFERROR(_xlfn.SWITCH($H40, 0, $C$4, 1, $D$4, 2, $E$4, 3, $F$4, "Error") * $G40, "Error") -> 0
B41: Creación dinámica | C41: No utiliza o utiliza sin sentido | F41: Utiliza con sentido | G41: 0.5 | I41: =IFERROR(_xlfn.SWITCH($H41, 0, $C$4, 1, $D$4, 2, $E$4, 3, $F$4, "Error") * $G41, "Error") -> 0
B42: Errores DOM | C42: No presenta errores | D42: Presenta un error | E42: Presenta dos errores | F42: Presenta tres o más errores | G42: -0.5 | I42: =IFERROR(_xlfn.SWITCH($H42, 0, $C$4, 1, $D$4, 2, $E$4, 3, $F$4, "Error") * $G42, "Error") -> 0
...

Sheet Nota Transversales
C1: RETO 1 - Notas Transversales
A5: Configuración
A6: Diferencia máx: | B6: 3
A7: Horas totales Reto | B7: 36 | D7: 0.4 | I7: 0.1 | N7: 0.5 | P7: 1
D8: T.Equipo | I8: Planificacion | N8: C.Oral | O8: Faltas | P8: Final
D9: 0.5 | E9: 0.3 | F9: 0.2 | I9: 0.5 | J9: 0.3 | K9: 0.2
C10: Izena | D10: Prof. | E10: Coev. | F10: Auto. | G10: Dif. | H10: Total | I10: Prof. | J10: Coev. | K10: Auto. | L10: Dif. | M10: Total | N10: Prof. | O10: % Total | P10: Total | R10: Faltas durante Reto
C11: =Portada!$K11 -> Name | G11: =IFERROR(IF(OR(ABS(D11-F11)>=$B$6,ABS(E11-F11)>=$B$6),"Dif",""), "") | H11: =IFERROR(IF(G11="Dif", D11, D11*D$9+E11*E$9+F11*F$9), "") -> 0 | L11: =IFERROR(IF(OR(ABS(I11-K11)>=$B$6,ABS(J11-K11)>=$B$6),"Dif",""), "") | M11: =IFERROR(IF(L11="Dif", I11, I11*I$9+J11*J$9+K11*K$9), "") -> 0 | O11: =$R11/36 -> 0 | P11: =IF((O11 >= 0.2), MIN(4, $H11*$D$7+$M11*$I$7+$N11*$N$7), $H11*$D$7+$M11*$I$7+$N11*$N$7) -> 0 | R11: 0
C12: =Portada!$K12 -> Name | G12: =IFERROR(IF(OR(ABS(D12-F12)>=$B$6,ABS(E12-F12)>=$B$6),"Dif",""), "") | H12: =IFERROR(IF(G12="Dif", D12, D12*D$9+E12*E$9+F12*F$9), "") -> 0 | L12: =IFERROR(IF(OR(ABS(I12-K12)>=$B$6,ABS(J12-K12)>=$B$6),"Dif",""), "") | M12: =IFERROR(IF(L12="Dif", I12, I12*I$9+J12*J$9+K12*K$9), "") -> 0 | O12: =$R12/36 -> 0 | P12: =IF((O12 >= 0.2), MIN(4, $H12*$D$7+$M12*$I$7+$N12*$N$7), $H12*$D$7+$M12*$I$7+$N12*$N$7) -> 0 | R12: 0
C13: =Portada!$K13 -> - | G13: =IFERROR(IF(OR(ABS(D13-F13)>=$B$6,ABS(E13-F13)>=$B$6),"Dif",""), "") | H13: =IFERROR(IF(G13="Dif", D13, D13*D$9+E13*E$9+F13*F$9), "") -> 0 | L13: =IFERROR(IF(OR(ABS(I13-K13)>=$B$6,ABS(J13-K13)>=$B$6),"Dif",""), "") | M13: =IFERROR(IF(L13="Dif", I13, I13*I$9+J13*J$9+K13*K$9), "") -> 0 | O13: =$R13/36 -> 0 | P13: =IF((O13 >= 0.2), MIN(4, $H13*$D$7+$M13*$I$7+$N13*$N$7), $H13*$D$7+$M13*$I$7+$N13*$N$7) -> 0 | R13: 0
C14: =Portada!$K14 -> - | G14: =IFERROR(IF(OR(ABS(D14-F14)>=$B$6,ABS(E14-F14)>=$B$6),"Dif",""), "") | H14: =IFERROR(IF(G14="Dif", D14, D14*D$9+E14*E$9+F14*F$9), "") -> 0 | L14: =IFERROR(IF(OR(ABS(I14-K14)>=$B$6,ABS(J14-K14)>=$B$6),"Dif",""), "") | M14: =IFERROR(IF(L14="Dif", I14, I14*I$9+J14*J$9+K14*K$9), "") -> 0 | O14: =$R14/36 -> 0 | P14: =IF((O14 >= 0.2), MIN(4, $H14*$D$7+$M14*$I$7+$N14*$N$7), $H14*$D$7+$M14*$I$7+$N14*$N$7) -> 0 | R14: 0
C15: Alumno 10 | D15: 10 | E15: 10 | F15: 10 | G15: =IFERROR(IF(OR(ABS(D15-F15)>=$B$6,ABS(E15-F15)>=$B$6),"Dif",""), "") | H15: =IFERROR(IF(G15="Dif", D15, D15*D$9+E15*E$9+F15*F$9), "") -> 10 | I15: 10 | J15: 10 | K15: 10 | L15: =IFERROR(IF(OR(ABS(I15-K15)>=$B$6,ABS(J15-K15)>=$B$6),"Dif",""), "") | M15: =IFERROR(IF(L15="Dif", I15, I15*I$9+J15*J$9+K15*K$9), "") -> 10 | N15: 10 | O15: =$R15/36 -> 0 | P15: =IF((O15 >= 0.2), MIN(4, $H15*$D$7+$M15*$I$7+$N15*$N$7), $H15*$D$7+$M15*$I$7+$N15*$N$7) -> 10

Sheet Técnicas Nota
B1: RETO 1 - Notas Tecnicas
B4: GRUPO
F5: =Portada!$K11 -> Name | K5: =Portada!$K12 -> Name
B6: ALUMNOS | F6: MODULO | G6: NOTA GRUPO | H6: Variación | I6: NOTA TECNICAS | K6: MODULO | L6: NOTA GRUPO | M6: Variación | N6: NOTA TECNICAS
B7: =Portada!$J11 -> 1 | C7: =Portada!$K11 -> Name | F7: DIW | G7: =DIW!$I$9 + DIW!$I$26 -> 0 | H7: 0 | I7: =IFERROR(ROUND(G7*(H7), 2),0) -> 0 | K7: DIW | L7: =DIW!$I$9 + DIW!$I$26 -> 0 | M7: 0 | N7: =IFERROR(ROUND(L7*(M7), 2),0) -> 0
B8: =Portada!$J12 -> 2 | C8: =Portada!$K12 -> Name | F8: DWEC | G8: =DWEC!$I$47 -> 0 | H8: 0 | I8: =IFERROR(ROUND(G8*(H8), 2),0) -> 0 | K8: DWEC | L8: =DWEC!$I$47 -> 0 | M8: 0 | N8: =IFERROR(ROUND(L8*(M8), 2),0) -> 0
B9: =Portada!$J13 -> 3 | C9: =Portada!$K13 -> -
B10: =Portada!$J14 -> 4 | C10: =Portada!$K14 -> - | F10: =Portada!$K13 -> - | K10: =Portada!$K14 -> -
F11: MODULO | G11: NOTA GRUPO | H11: Variación | I11: NOTA TECNICAS | K11: MODULO | L11: NOTA GRUPO | M11: Variación | N11: NOTA TECNICAS
B12: Variación - el % que modifica la nota de cada alumno por su trabajo individual. Ese valor se especifica en la pestaña de su módulo correspondiente. Se traslada a mano a este página. | F12: DIW | G12: =DIW!$I$9 + DIW!$I$26 -> 0 | H12: 0 | I12: =IFERROR(ROUND(G12*(H12), 2),0) -> 0 | K12: DIW | L12: =DIW!$I$9 + DIW!$I$26 -> 0 | M12: 0 | N12: =IFERROR(ROUND(L12*(M12), 2),0) -> 0
F13: DWEC | G13: =DWEC!$I$47 -> 0 | H13: 0 | I13: =IFERROR(ROUND(G13*(H13), 2),0) -> 0 | K13: DWEC | L13: =DWEC!$I$47 -> 0 | M13: 0 | N13: =IFERROR(ROUND(L13*(M13), 2),0) -> 0
F16: Alumno 10 (Pruebas)
F17: MODULO | G17: NOTA GRUPO | H17: Variación | I17: NOTA TECNICAS
F18: ¿¿?? | G18: 10 | H18: 0.66 | I18: =IFERROR(ROUND(G18*(H18), 2),0) -> 6.6
